Workbook

Sheet state_to_region
A1: State | B1: =MAP!C1 -> Region
A2: CA | B2: =MAP!C2 -> West
A3: TX | B3: =MAP!C3 -> East
A4: FL | B4: =MAP!C4 -> East
A5: NV | B5: =MAP!C5 -> West
A6: NY | B6: =MAP!C6 -> East
A7: WA | B7: =MAP!C7 -> West
A8: AZ | B8: =MAP!C8 -> West
A9: KY | B9: =MAP!C9 -> East
A10: MD | B10: =MAP!C10 -> East
A11: DC | B11: =MAP!C11 -> East
A12: LA | B12: =MAP!C12 -> West
... A32: CT | B32: =MAP!C32 -> East
A33: NC | B33: Control
A34: MI | B34: Control
A35: UT | B35: Control
A36: NH | B36: Control
A37: VA | B37: Control
A38: OH | B38: Control
A39: PA | B39: Control
A40: OR | B40: Control
A41: MS | B41: Control
A42: ME | B42: Control
A43: MT | B43: Control
A44: WY | B44: Control
... A49: AL | B49: Control

Sheet state_to_sgws_region
A1: State | B1: =MAP!B1 -> SGWS Region
A2: CA | B2: =MAP!B2 -> West
A3: TX | B3: =MAP!B3 -> Central
A4: FL | B4: =MAP!B4 -> East
A5: NV | B5: =MAP!B5 -> West
A6: NY | B6: =MAP!B6 -> East
A7: WA | B7: =MAP!B7 -> West
A8: AZ | B8: =MAP!B8 -> West
A9: KY | B9: =MAP!B9 -> East
A10: MD | B10: =MAP!B10 -> East
A11: DC | B11: =MAP!B11 -> East
A12: LA | B12: =MAP!B12 -> Central
... A32: CT | B32: =MAP!B32 -> Non-SGWS
A33: NC | B33: Control
A34: MI | B34: Control
A35: UT | B35: Control
A36: NH | B36: Control
A37: VA | B37: Control
A38: OH | B38: Control
A39: PA | B39: Control
A40: OR | B40: Control
A41: MS | B41: Control
A42: ME | B42: Control
A43: MT | B43: Control
A44: WY | B44: Control
... A49: AL | B49: Control

Sheet MAP
A1: State | B1: SGWS Region | C1: Region
A2: CA | B2: West | C2: =_xlfn.XLOOKUP(A2,original_MAP!A:A,original_MAP!C:C) -> West
A3: TX | B3: Central | C3: =_xlfn.XLOOKUP(A3,original_MAP!A:A,original_MAP!C:C) -> East
A4: FL | B4: East | C4: =_xlfn.XLOOKUP(A4,original_MAP!A:A,original_MAP!C:C) -> East
A5: NV | B5: West | C5: =_xlfn.XLOOKUP(A5,original_MAP!A:A,original_MAP!C:C) -> West
A6: NY | B6: East | C6: =_xlfn.XLOOKUP(A6,original_MAP!A:A,original_MAP!C:C) -> East
A7: WA | B7: West | C7: =_xlfn.XLOOKUP(A7,original_MAP!A:A,original_MAP!C:C) -> West
A8: AZ | B8: West | C8: =_xlfn.XLOOKUP(A8,original_MAP!A:A,original_MAP!C:C) -> West
A9: KY | B9: East | C9: =_xlfn.XLOOKUP(A9,original_MAP!A:A,original_MAP!C:C) -> East
A10: MD | B10: East | C10: =_xlfn.XLOOKUP(A10,original_MAP!A:A,original_MAP!C:C) -> East
A11: DC | B11: East | C11: =_xlfn.XLOOKUP(A11,original_MAP!A:A,original_MAP!C:C) -> East
A12: LA | B12: Central | C12: =_xlfn.XLOOKUP(A12,original_MAP!A:A,original_MAP!C:C) -> West
A13: IL | B13: Central | C13: =_xlfn.XLOOKUP(A13,original_MAP!A:A,original_MAP!C:C) -> East
... A32: CT | B32: Non-SGWS | C32: =_xlfn.XLOOKUP(A32,original_MAP!A:A,original_MAP!C:C) -> East

Sheet original_MAP
A1: Market | B1: SGWS-AO | C1: Region | D1: SGWS-Control-AO | E1: SGWS Region | H1: State | I1: SGWS Region | J1: Region
A2: SoCal | B2: SGWS | C2: West | D2: SGWS Open | E2: West | H2: CA | I2: West | J2: =_xlfn.XLOOKUP(H2,A:A,C:C) -> West
A3: NoCal | B3: SGWS | C3: West | D3: SGWS Open | E3: West | H3: TX | I3: Central | J3: =_xlfn.XLOOKUP(H3,A:A,C:C) -> East
A4: NV Las Vegas | B4: SGWS | C4: West | D4: SGWS Open | E4: West | H4: FL | I4: East | J4: =_xlfn.XLOOKUP(H4,A:A,C:C) -> East
A5: NV Sparks | B5: SGWS | C5: West | D5: SGWS Open | E5: West | H5: NV | I5: West | J5: =_xlfn.XLOOKUP(H5,A:A,C:C) -> West
A6: CO | B6: SGWS | C6: West | D6: SGWS Open | E6: Central | H6: NY | I6: East | J6: =_xlfn.XLOOKUP(H6,A:A,C:C) -> East
A7: AZ | B7: SGWS | C7: West | D7: SGWS Open | E7: West | H7: WA | I7: West | J7: =_xlfn.XLOOKUP(H7,A:A,C:C) -> West
A8: LA | B8: SGWS | C8: West | D8: SGWS Open | E8: Central | H8: AZ | I8: West | J8: =_xlfn.XLOOKUP(H8,A:A,C:C) -> West
A9: HI | B9: SGWS | C9: West | D9: SGWS Open | E9: West | H9: KY | I9: East | J9: =_xlfn.XLOOKUP(H9,A:A,C:C) -> East
A10: WA | B10: SGWS | C10: West | D10: SGWS Open | E10: West | H10: MD | I10: East | J10: =_xlfn.XLOOKUP(H10,A:A,C:C) -> East
A11: NM | B11: SGWS | C11: West | D11: SGWS Open | E11: West | H11: DC | I11: East | J11: =_xlfn.XLOOKUP(H11,A:A,C:C) -> East
A12: AK | B12: SGWS | C12: West | D12: SGWS Open | E12: West | H12: LA | I12: Central | J12: =_xlfn.XLOOKUP(H12,A:A,C:C) -> West
A13: NY Metro | B13: SGWS | C13: East | D13: SGWS Open | E13: East | H13: IL | I13: Central | J13: =_xlfn.XLOOKUP(H13,A:A,C:C) -> East
... A23: TN SGWS | B23: SGWS | C23: East | D23: SGWS Open | E23: Central | H23: KS | I23: Central | J23: =_xlfn.XLOOKUP(H23,A:A,C:C) -> Central
A24: MA | B24: AO | C24: East | D24: AO | H24: MN | I24: Central | J24: =_xlfn.XLOOKUP(H24,A:A,C:C) -> Central
A25: CT | B25: AO | C25: East | D25: AO | H25: AK | I25: West | J25: =_xlfn.XLOOKUP(H25,A:A,C:C) -> West
A26: IN | B26: SGWS | C26: East | D26: SGWS Open | H26: AR | I26: Central | J26: =_xlfn.XLOOKUP(H26,A:A,C:C) -> Central
A27: MD | B27: SGWS | C27: East | D27: SGWS Open | H27: SD | I27: Central | J27: =_xlfn.XLOOKUP(H27,A:A,C:C) -> Central
A28: DC | B28: SGWS | C28: East | D28: SGWS Open | H28: ND | I28: Central | J28: =_xlfn.XLOOKUP(H28,A:A,C:C) -> Central
A29: SC | B29: SGWS | C29: East | D29: SGWS Open | H29: TN | I29: Central | J29: =_xlfn.XLOOKUP(H29,A:A,C:C) -> East
A30: WI | B30: AO | C30: East | D30: AO | H30: VA | I30: Control | J30: =_xlfn.XLOOKUP(H30,A:A,C:C) -> Control
A31: RI | B31: AO | C31: East | D31: AO | H31: IA | I31: Control | J31: =_xlfn.XLOOKUP(H31,A:A,C:C) -> Control
A32: KY | B32: SGWS | C32: East | D32: SGWS Open | H32: CT | I32: Non-SGWS | J32: =_xlfn.XLOOKUP(H32,A:A,C:C) -> East
A33: DE | B33: SGWS | C33: East | D33: SGWS Open
A34: NC | B34: SGWS | C34: Control | D34: Control
A35: MI | B35: SGWS | C35: Control | D35: Control
A36: UT | B36: SGWS | C36: Control | D36: Control
A37: NH | B37: SGWS | C37: Control | D37: Control
A38: VA | B38: SGWS | C38: Control | D38: Control
A39: OH | B39: SGWS | C39: Control | D39: Control
A40: PA | B40: SGWS | C40: Control | D40: Control
A41: OR | B41: SGWS | C41: Control | D41: Control
A42: MS | B42: SGWS | C42: Control | D42: Control
A43: ME | B43: SGWS | C43: Control | D43: Control
A44: MT | B44: SGWS | C44: Control | D44: Control
... A60: TX San Antonio | B60: SGWS | C60: Central | D60: SGWS Open
A61: XX
A62: NJ | B62: AO | C62: East | D62: AO
A63: TX | B63: SGWS | C63: East | D63: SGWS Open
A64: TN | B64: SGWS | C64: East | D64: SGWS Open
...
